<?xml version="1.0"?>
<!-- 深度相机放在前面 扫前面 雷达放在后面 -->
<robot name="robot" xmlns:xacro="http://www.ros.org/wiki/xacro">

    <xacro:property name="length_wheel" value="0.05" />
    <xacro:property name="radius_wheel" value="0.06" />
    <xacro:property name="PI" value="3.1415926"/>
    <xacro:macro name="default_inertial" params="mass">
        <inertial>
            <mass value="${mass}" />
            <inertia ixx="0.01" ixy="0.0" ixz="0.0"
                     iyy="0.01" iyz="0.0" izz="0.01" />
        </inertial>
    </xacro:macro>

    <link name="base_footprint"/>

    <joint name="base_to_footprint" type="fixed">
        <parent link="base_footprint"/>
        <child link="base_link"/>
        <origin rpy="0 0 0" xyz="0 0 0.06"/>
    </joint>

    <link name="base_link">
        <visual>
            <geometry>
                <box size="0.2 0.4 0.1"/>
            </geometry>
            <origin rpy="0 0 ${PI/2}" xyz="0 0 0.05"/>  
            <material name="white">
                <color rgba="1 1 1 1"/>
            </material>
        </visual>
        <collision>
            <geometry>
                <box size="0.2 0.3 0.1"/>
            </geometry>
        </collision>
        <xacro:default_inertial mass="8.2"/>    
    </link>

    <link name="gimbal_yaw">
        <visual>
            <geometry>
                <box size="0.2 0.3 0.01"/>
            </geometry>
            <origin rpy="0 0 ${PI/2}" xyz="0 0 0.05"/>  
            <material name="red">
                <color rgba="1 0 0 1"/>
            </material>
        </visual>
        <collision>
            <geometry>
                <box size="0.2 0.3 0.01"/>
            </geometry>
        </collision>
        <xacro:default_inertial mass="8.2"/>    
    </link>

    <joint name="base_to_gimbal_yaw" type="fixed">
        <parent link="base_link"/>
        <child link="gimbal_yaw"/>
        <origin rpy="0 0 0" xyz="0 0 0.055"/>
    </joint>

    <link name="wheel_1">
        <visual>
            <geometry>
                <cylinder length="${length_wheel}" radius="${radius_wheel}"/>
            </geometry>
            <origin rpy="0 0 0" xyz="0 0 0"/>
            <material name="black">
                <color rgba="0 0 0 1"/>
            </material>
        </visual>
        <collision>
            <geometry>
                <cylinder length="${length_wheel}" radius="${radius_wheel}"/>
            </geometry>
        </collision>
        <mu1>0.5</mu1>
        <mu2>0.5</mu2>
        <xacro:default_inertial mass="0.5"/>  
    </link>

    <link name="wheel_2">
        <visual>
            <geometry>
                <cylinder length="${length_wheel}" radius="${radius_wheel}"/>
            </geometry>
            <origin rpy="0 0 0" xyz="0 0 0"/>
            <material name="black"/>
        </visual>
        <collision>
            <geometry>
                <cylinder length="${length_wheel}" radius="${radius_wheel}"/>
            </geometry>
        </collision>
        <mu1>0.5</mu1>
        <mu2>0.5</mu2>
        <xacro:default_inertial mass="0.5"/>  
    </link>
 
    <link name="wheel_3">
        <visual>
            <geometry>
                <cylinder length="${length_wheel}" radius="${radius_wheel}"/>
            </geometry>
            <origin rpy="0 0 0" xyz="0 0 0"/>
            <material name="black"/>
        </visual>
        <collision>
            <geometry>
                <cylinder length="${length_wheel}" radius="${radius_wheel}"/>
            </geometry>
        </collision>
        <mu1>0.5</mu1>
        <mu2>0.5</mu2>
        <xacro:default_inertial mass="0.5"/>    
    </link>

    <link name="wheel_4">
        <visual>
            <geometry>
                <cylinder length="${length_wheel}" radius="${radius_wheel}"/>
            </geometry>
            <origin rpy="0 0 0" xyz="0 0 0" />
            <material name="black"/>
        </visual>
        <collision>
            <geometry>
                <cylinder length="${length_wheel}" radius="${radius_wheel}"/>
            </geometry>
        </collision>
        <mu1>0.5</mu1>
        <mu2>0.5</mu2>
        <xacro:default_inertial mass="0.5"/>    
    </link>

    <joint name="base_to_wheel1" type="continuous">
        <parent link="base_link"/>
        <child link="wheel_1"/>
        <origin rpy="${-PI/2} 0 0" xyz="0.1 0.13 0"/>
        <axis xyz="0 0 1" />
    </joint>

    <joint name="base_to_wheel2" type="continuous">
        <axis xyz="0 0 1" />
        <anchor xyz="0 0 0" />
        <limit effort="100" velocity="100" />
        <parent link="base_link"/>
        <child link="wheel_2"/>
        <origin rpy="${-PI/2} 0 0" xyz="-0.1 0.13 0"/>
    </joint>

    <joint name="base_to_wheel3" type="continuous">
        <parent link="base_link"/>
        <axis xyz="0 0 1" />
        <child link="wheel_3"/>
        <origin rpy="${-PI/2} 0 0" xyz="0.1 -0.13 0"/>
    </joint>

    <joint name="base_to_wheel4" type="continuous">
        <parent link="base_link"/>
        <axis xyz="0 0 1" />
        <child link="wheel_4"/>
        <origin rpy="${-PI/2} 0 0" xyz="-0.1 -0.13 0"/>
    </joint>
    
    <!-- IMU -->
    <joint name="imu_joint" type="fixed">
        <axis xyz="0 1 0" />
        <origin xyz="0 0 0.13" rpy="0 0 0"/> 
        <parent link="base_link"/>
        <child link="imu_link"/>
    </joint>

    <link name="imu_link">
        <collision>
            <origin xyz="0 0 0" rpy="0 0 0"/>
            <geometry>
                <box size="0.05 0.05 0.05"/>
            </geometry>
        </collision>

        <visual>
            <origin xyz="0 0 0" rpy="0 0 0"/>
            <geometry>
                <box size="0.05 0.05 0.05"/>
            </geometry>
            <material name="green">
                <color rgba="0 1 0 1"/>
            </material>
        </visual>

        <inertial>
            <mass value="1e-2" />
            <origin xyz="0 0 0" rpy="0 0 0"/>
            <inertia ixx="1e-6" ixy="0" ixz="0" iyy="1e-6" iyz="0" izz="1e-6" />
        </inertial>
    </link>


    <!-- Camera -->
    <!-- <link name="camera_link">
        <visual>
            <origin xyz="0 0 0.0" rpy="0 0 0" /> 
            <geometry>
                <box size="0.02 0.10 0.02" />
            </geometry>
            <material name="black">
                <color rgba="0 0 0 0.8"/>
            </material>
        </visual>
        <collision>
            <origin xyz="0 0 0.05" rpy="0 0 0" /> 
            <geometry>
                <box size="0.02 0.10 0.02" />
            </geometry>
            <material name="black">
                <color rgba="0 0 0 0"/>
            </material>
        </collision>
        <xacro:default_inertial mass="0.5"/>
    </link>

    <link name="camera_optical_link"></link>

    <joint name="camera_optical_joint" type="fixed">
        <parent link="camera_link" />
        <child link="camera_optical_link" />
        <origin xyz="0 0 0" rpy="${-PI/2} 0 ${-PI/2}" />
    </joint>

    <joint name="camera_joint" type="fixed">
        <parent link="base_link" /> 
        <child link="camera_link" />
        <origin xyz="0.13 0 0.12" rpy="0 0 0"/> 
    </joint> -->

    <!-- Livox-Mid360 -->
    <!-- <link name="livox_frame">

    </link>

    <joint name="livox_joint" type="fixed">
        <origin xyz="-0.1 0 0.13" rpy="0 0 0"/> 
        <parent link="base_link" />
        <child link="livox_frame"/>
    </joint> -->

    <!-- gazebo插件设置相关 -->
    <gazebo reference="base_link">
        <material>Gazebo/Orange</material>
    </gazebo>

    <gazebo reference="gimbal_yaw">
        <material>Gazebo/Red</material>
    </gazebo>

    <gazebo reference="wheel_1">
        <material>Gazebo/Red</material>
    </gazebo>

    <gazebo reference="wheel_2">
        <material>Gazebo/Black</material>
    </gazebo>

    <gazebo reference="wheel_3">
        <material>Gazebo/Red</material>
    </gazebo>

    <gazebo reference="wheel_4">
        <material>Gazebo/Black</material>
    </gazebo>

    <gazebo>
        <plugin name="mecanum_controller" filename="libgazebo_ros_planar_move.so">
            <ros>
             
                <remapping>cmd_vel:=cmd_vel</remapping>
                <remapping>odom:=odom</remapping>
            </ros>

            <update_rate>100</update_rate>
            <publish_rate>100</publish_rate>

            <publish_odom>false</publish_odom>
            <publish_odom_tf>false</publish_odom_tf>

            <leftFrontJoint>base_to_wheel1</leftFrontJoint>
            <rightFrontJoint>base_to_wheel3</rightFrontJoint>
            <leftRearJoint>base_to_wheel2</leftRearJoint>
            <rightRearJoint>base_to_wheel4</rightRearJoint>
            <wheelSeparation>0.26</wheelSeparation>
            <wheelDiameter>0.12</wheelDiameter>
        </plugin>
    </gazebo>

    <!-- <gazebo reference="camera_link">
        <sensor type="depth" name="camera_sensor">
            <plugin name="depth_camera" filename="libgazebo_ros_camera.so">
                <frame_name>camera_optical_link</frame_name>
            </plugin>
            <always_on>true</always_on>
            <update_rate>10</update_rate>
            <camera name="camera">
                <horizontal_fov>1.5009831567</horizontal_fov>
                <image>
                    <width>800</width>
                    <height>600</height>
                    <format>R8G8B8</format>
                </image>
                <distortion>
                    <k1>0.0</k1>
                    <k2>0.0</k2>
                    <k3>0.0</k3>
                    <p1>0.0</p1>
                    <p2>0.0</p2>
                    <center>0.5 0.5</center>
                </distortion>
            </camera>
        </sensor>
    </gazebo> -->

    <gazebo reference="imu_link">
        <material>Gazebo/Orange</material>
        <gravity>true</gravity>
        <sensor name="imu_sensor" type="imu">
            <always_on>true</always_on>
            <update_rate>100</update_rate>
            <visualize>true</visualize>
            <topic>__default_topic__</topic>
            <plugin filename="libgazebo_ros_imu_sensor.so" name="imu_plugin">
                <topicName>/livox/imu</topicName>
                <bodyName>imu_link</bodyName>
                <updateRateHZ>100.0</updateRateHZ>
                <gaussianNoise>0.0</gaussianNoise>
                <xyzOffset>0 0 0</xyzOffset>
                <rpyOffset>0 0 0</rpyOffset>
                <frameName>imu_link</frameName>
                <serviceName>default_service</serviceName>
                <alwaysOn>true</alwaysOn>
                <maxAngularVelocity>100.0</maxAngularVelocity>
                <noiseDensity>0.0</noiseDensity>
                <randomWalk>0.0</randomWalk>
                <ros>
                    <remapping>~/out:=/livox/imu</remapping>
                </ros>
            </plugin>
        </sensor>
    </gazebo>

    <xacro:include filename="$(find ros2_livox_simulation)/urdf/mid360.xacro" />
    <xacro:mid360 name="livox_frame" parent="base_link" topic="/livox/lidar">
        <origin xyz="0 0 0.2" rpy="0 0 0"/> 
    </xacro:mid360>

        <!-- 在原来的位置上添加一个长方体 -->
    <!-- <link name="additional_block">
        <visual>
            <geometry>
                <box size="0.1 0.1 0.2"/>
            </geometry>
            <origin rpy="0 0 0" xyz="0 0 0.125"/>
            <material name="blue">
                <color rgba="0 0 1 1"/>
            </material>
        </visual>
        <collision>
            <geometry>
                <box size="0.05 0.05 0.1"/>
            </geometry>
        </collision>
        <xacro:default_inertial mass="0.1"/>
    </link>

    <joint name="base_to_additional_block" type="fixed">
        <parent link="base_link"/>
        <child link="additional_block"/>
        <origin rpy="0 0 0" xyz="0 0 0"/>
    </joint> -->
</robot>
